Workbook

Sheet calc
A1: void test_contract::test_manual_referenceCase_payoutImmediateThenDeferred()
B4: Zins | C4: 0.015
B5: interest model | C5: payout | D5: =_xlfn.XLOOKUP(C5,helper!$A$7:$A$10,helper!$B$7:$B$10) -> 0
B6: Zinsusance | C6: 30-360 | D6: =_xlfn.XLOOKUP(C6,helper!$A$3:$A$4,helper!$B$3:$B$4) -> 4
B7: Unterjähriger Zins? | C7: ja
A9: conclusion | B9: 45627
B11: startwert | C11: von | D11: bis | E11: Zins | F11: Zins Auszahlung? | G11: änderung | H11: Endwert | I11: verzinslich | J11: Buchungen | K11: # buchungen
A12: initial deposit | B12: 0 | D12: 45656 | H12: 1000 | I12: =H12 -> 1000 | J12: 1 | K12: 1
A13: annual settlement 2024 deposit |payout | B13: =I12 -> 1000 | C13: =D12 -> 45656 | D13: 45657 | E13: =YEARFRAC(C13,D13,$D$6)*$C$4*I12 -> 0 | F13: =E13 -> 0 | G13: 0 | H13: =B13+E13+F13+G13 -> 1000 | I13: =H13 -> 1000 | J13: 2, 8 | K13: 3
A14: deposit | interest payout | B14: =I13 -> 1000 | C14: =D13 -> 45657 | D14: 45731 | E14: =YEARFRAC(C14,D14,$D$6)*$C$4*I13 -> 3.125 | F14: =-E14 -> -3.125 | G14: 500 | H14: =B14+E14+F14+G14 -> 1500 | I14: =H14 -> 1500 | J14: 2, 4 | K14: 5
A15: annual settlement 2025 deposit |payout | B15: =I14 -> 1500 | C15: =D14 -> 45731 | D15: 46022 | E15: =YEARFRAC(C15,D15,$D$6)*$C$4*I14 -> 17.8125 | F15: =-E15 -> -17.8125 | G15: 0 | H15: =B15+E15+F15+G15 -> 1500 | I15: =H15 -> 1500 | J15: 1,2,8 | K15: 8
A16: payout | deferred interest | B16: =I15 -> 1500 | C16: 46022 | D16: 46174 | G16: -500 | H16: =B16+G16 -> 1000 | I16: =H16 -> 1000 | J16: 32, 2 | K16: 10
A17: deposit | deferred interest | B17: =I16 -> 1000 | C17: =D16 -> 46174 | D17: 46296 | G17: 100 | H17: =B17+G17 -> 1100 | I17: =H17 -> 1100 | J17: 1 | K17: 11
A18: annual settlement 2026 | B18: 1500 | C18: =C16 -> 46022 | D18: 46387 | E18: =YEARFRAC(C18,D18,$D$6)*$C$4*B18 -> 22.5 | F18: =E18+E17+E16 -> 22.5 | H18: =B18+F18 -> 1522.5
A19: annual settlement 2026 payout | B19: =G16 -> -500 | C19: =D16 -> 46174 | D19: 46387 | E19: =YEARFRAC(C19,D19,$D$6)*$C$4*B19 -> -4.3541667 | F19: =E19 -> -4.3541667 | H19: =H18+F19 -> 1518.1458
A20: annual settlement 2026 deposit | B20: 100 | C20: 46296 | D20: 46387 | E20: =YEARFRAC(C20,D20,$D$6)*$C$4*B20 -> 0.37083333 | F20: =E20 -> 0.37083333 | H20: =H19+F20 -> 1518.5167
E21: =SUM(E18:E20) -> 18.516667 | J21: 1 | K21: 12
A24: test_manual_referenceCase_payoutImmediateThenDeferred_actAct()
B26: Zins | C26: 0.015
B27: interest model | C27: payout | D27: =_xlfn.XLOOKUP(C27,helper!$A$7:$A$10,helper!$B$7:$B$10) -> 0
B28: Zinsusance | C28: Act-Act | D28: =_xlfn.XLOOKUP(C28,helper!$A$3:$A$4,helper!$B$3:$B$4) -> 1
B29: Unterjähriger Zins? | C29: ja
A31: conclusion | B31: 45627
B33: startwert | C33: von | D33: bis | E33: Zins | F33: Zins Auszahlung? | G33: änderung | H33: Endwert | I33: verzinslich | J33: Buchungen | K33: # buchungen
A34: initial deposit | B34: 0 | D34: 45656 | H34: 1000 | I34: =H34 -> 1000 | J34: 1 | K34: 1
A35: impl. Annual settlement deposit | payout | B35: =I34 -> 1000 | C35: =D34 -> 45656 | D35: 45657 | E35: =YEARFRAC(C35,D35,$D$28)*$C$26*B35 -> 0.040983607 | F35: =-E35 -> -0.040983607 | H35: =B35+E35+F35 -> 1000 | I35: =H35 -> 1000 | J35: 2, 8 | K35: 3
A36: deposit | B36: =I35 -> 1000 | C36: =D35 -> 45657 | D36: 45731 | E36: =YEARFRAC(C36,D36,$D$28)*$C$26*B36 -> 3.0410959 | F36: =-E36 -> -3.0410959 | G36: 500 | H36: =B36+E36+F36+G36 -> 1500 | I36: =H36 -> 1500 | J36: 2.4 | K36: 5
A37: annual settlement 2025 | B37: =I36 -> 1500 | C37: =D36 -> 45731 | D37: 46022 | E37: =YEARFRAC(C37,D37,$D$28)*$C$26*B37 -> 17.938356 | F37: =-E37 -> -17.938356 | H37: =B37+E37+F37 -> 1500 | I37: =H37 -> 1500 | J37: 2,1, 8 | K37: 8
A38: payout | deferred interest | B38: =I37 -> 1500 | C38: =D37 -> 46022 | D38: 45809 | G38: -500 | H38: =B38+G38 -> 1000 | I38: =H38 -> 1000 | J38: 32.2 | K38: 10
A39: deposit | deferred interest | B39: =I38 -> 1000 | C39: =D38 -> 45809 | D39: 45931 | G39: 100 | H39: =B39+G39 -> 1100 | I39: =H39 -> 1100 | J39: 1 | K39: 11
A40: annual settlement 2026 | B40: =H37 -> 1500 | C40: 46022 | D40: 46387 | E40: =YEARFRAC(C40,D40,$D$28)*$C$26*B40 -> 22.5 | F40: =-E40 -> -22.5
A41: annual settlement 2026 payout | B41: =G38 -> -500 | C41: 46174 | D41: 46387 | E41: =YEARFRAC(C41,D41,$D$28)*$C$26*B41 -> -4.3767123 | F41: =-E41 -> 4.3767123
A42: annual settlement 2026 deposit | B42: 100 | C42: 46296 | D42: 46387 | E42: =YEARFRAC(C42,D42,$D$28)*$C$26*B42 -> 0.3739726 | F42: =-E42 -> -0.3739726
E43: =SUM(E40:E42) -> 18.49726 | J43: 8 | K43: 12
A46: test_manual_referenceCase_reinvestImmediateThenDeferred
B48: Zins | C48: 0.015
B49: interest model | C49: deposit | D49: =_xlfn.XLOOKUP(C49,helper!$A$7:$A$10,helper!$B$7:$B$10) -> 1
B50: Zinsusance | C50: 30-360 | D50: =_xlfn.XLOOKUP(C50,helper!$A$3:$A$4,helper!$B$3:$B$4) -> 4
B51: Unterjähriger Zins? | C51: ja
A53: conclusion | B53: 45627
...

Sheet helper
A2: Zinsusanze | B2: Wert
A3: Act-Act | B3: 1
A4: 30-360 | B4: 4
A7: payout | B7: 0
A8: deposit | B8: 1
A9: zero | B9: 2
A10: fixed | B10: 3
